Workbook

Sheet VENDAS_PCP
E1: Pedido ALUFORCE LTDA. RUA ERNESTINA 270 - VILA SÃO JOÃO - 08537400 - FERRAZ DE VASCONCELOS - SP
A4: Orçamento: | D4: Revisão: | F4: Pedido: | H4: Dt. liberação:
A6: VENDEDOR: | F6: Prazo de entrega:
A7: Cliente:
A8: Contato: | G8: Fone:
A9: Email: | H9: Frete: | J9: FOB
A11: Dados da transportadora:
A12: Nome: | G12: Fone:
A13: Cep: | E13: Endereço:
A14: Dados para cobrança:
A15: CPF/CNPJ: | F15: E-mail Nfe: | G15: =C9 -> 0
B17: Cod. | C17: Produto | F17: Embalagem: | G17: Lance(s) | H17: Qtd. | I17: V. Un. R$ | J17: V. Total. R$
A18: 1 | C18: =IFERROR(VLOOKUP(B18:B32,N176:O198,2,0),"") | J18: =I18*H18 -> 0
A19: 2 | C19: =IFERROR(VLOOKUP(B18:B32,N176:O199,2,0),"") | J19: =I19*H19 -> 0
A20: 3 | B20: ; | C20: =IFERROR(VLOOKUP(B18:B32,N176:O200,2,0),"") | J20: =I20*H20 -> 0
A21: 4 | C21: =IFERROR(VLOOKUP(B18:B32,N176:O201,2,0),"") | J21: =I21*H21 -> 0
A22: 5 | C22: =IFERROR(VLOOKUP(B18:B32,N176:O202,2,0),"") | J22: =I22*H22 -> 0
A23: 6 | C23: =IFERROR(VLOOKUP(B18:B32,N176:O199,2,0),"") | J23: =I23*H23 -> 0
A24: 7 | C24: =IFERROR(VLOOKUP(B24:B38,N176:O204,2,0),"") | J24: =I24*H24 -> 0
A25: 8 | C25: =IFERROR(VLOOKUP(B18:B32,N176:O198,2,0),"") | J25: =I25*H25 -> 0
A26: 9 | C26: =IFERROR(VLOOKUP(B18:B32,N176:O198,2,0),"") | J26: =I26*H26 -> 0
A27: 10 | C27: =IFERROR(VLOOKUP(B18:B32,N176:O207,2,0),"") | J27: =I27*H27 -> 0
A28: 11 | C28: =IFERROR(VLOOKUP(B18:B32,N176:O199,2,0),"") | J28: =I28*H28 -> 0
A29: 12 | C29: =IFERROR(VLOOKUP(B18:B32,N176:O198,2,0),"") | J29: =I29*H29 -> 0
A30: 13 | C30: =IFERROR(VLOOKUP(B18:B32,N176:O199,2,0),"") | J30: =I30*H30 -> 0
A31: 14 | C31: =IFERROR(VLOOKUP(B18:B32,N176:O199,2,0),"") | J31: =I31*H31 -> 0
A32: 15 | C32: =IFERROR(VLOOKUP(B18:B32,N176:O199,2,0),"") | J32: =I32*H32 -> 0
I34: Total do Pedido:$
I35: =SUM(J18:J32) -> 0
A36: Observações do Pedido
A43: CONDIÇOES DE PAGAMENTO.
A44: FORMAS DE PAGAMENTO | E44: % | F44: Método de Pagamento | I44: Valor Total $
A45: PARCELADO | E45: 1 | F45: FATURAMENTO | I45: =I35 -> 0
A46: ENTREGA | E46: =100%-E45 -> 0
A48: QTD - VOLUME: | D48: __________________________ | F48: EMBALAGEM: | H48: ___________________________
E50: OBSERVAÇÕES:
C51: COMPLETO
C53: PARCIAL

Sheet PRODUÇÃO
E1: Pedido ALUFORCE LTDA. RUA ERNESTINA 270 - VILA SÃO JOÃO - 08537400 - FERAZ DE VASCONCELOS - SP
A3: X
A4: Orçamento: | C4: =VENDAS_PCP!C4 -> 0 | D4: Revisão: | E4: =VENDAS_PCP!E4 -> 0 | F4: Pedido: | G4: =VENDAS_PCP!G4 -> 0 | H4: Dt. liberação: | J4: =VENDAS_PCP!J4 -> 0
A6: VENDEDOR: | C6: =VENDAS_PCP!C6 -> 0 | F6: Prazo de entrega: | H6: =VENDAS_PCP!H6 -> 0
A7: Cliente: | C7: =VENDAS_PCP!C7 -> 0
A8: Contato: | C8: =VENDAS_PCP!C8 -> 0 | G8: Fone: | H8: =VENDAS_PCP!H8 -> 0
A9: Email: | C9: =VENDAS_PCP!C9 -> 0 | H9: Frete: | J9: =VENDAS_PCP!J9 -> FOB
B12: Cod. | C12: Produto | F12: Cod. Cores | H12: Embalagem: | I12: Lance(s) | J12: Qtd.
A13: 1 | B13: =VENDAS_PCP!B18 -> 0 | C13: =IFERROR(VLOOKUP(B13:B56,#REF!,2,0),"") | F13: =IFERROR(VLOOKUP(B13,N180:P184,3,0),"") | H13: =VENDAS_PCP!F18 -> 0 | I13: =VENDAS_PCP!G18 -> 0 | J13: =VENDAS_PCP!H18 -> 0
A14: P. BRUTO | D14: P.LIQUIDO | F14: LOTE | H14: =H13 -> 0
A16: 2 | B16: =VENDAS_PCP!B19 -> 0 | C16: =IFERROR(VLOOKUP(B13:B56,#REF!,2,0),"") | F16: =IFERROR(VLOOKUP(B16,N180:P188,3,0),"") | H16: =VENDAS_PCP!F19 -> 0 | I16: =VENDAS_PCP!G19 -> 0 | J16: =VENDAS_PCP!H19 -> 0
A17: P. BRUTO | D17: P.LIQUIDO | F17: LOTE | H17: =H16 -> 0
A19: 3 | B19: =VENDAS_PCP!B20 -> ; | C19: =IFERROR(VLOOKUP(B13:B56,#REF!,2,0),"") | F19: =IFERROR(VLOOKUP(B19,N180:P188,3,0),"") | H19: =VENDAS_PCP!F20 -> 0 | I19: =VENDAS_PCP!G20 -> 0 | J19: =VENDAS_PCP!H20 -> 0
A20: P. BRUTO | D20: P.LIQUIDO | F20: LOTE | H20: =H19 -> 0
A22: 4 | B22: =VENDAS_PCP!B21 -> 0 | C22: =IFERROR(VLOOKUP(B13:B56,#REF!,2,0),"") | F22: =IFERROR(VLOOKUP(B22,N180:P186,3,0),"") | H22: =VENDAS_PCP!F21 -> 0 | I22: =VENDAS_PCP!G21 -> 0 | J22: =VENDAS_PCP!H21 -> 0
A23: P. BRUTO | D23: P.LIQUIDO | F23: LOTE | H23: =H22 -> 0
A25: 5 | B25: =VENDAS_PCP!B22 -> 0 | C25: =IFERROR(VLOOKUP(B13:B56,#REF!,2,0),"") | F25: =IFERROR(VLOOKUP(B25,N180:P188,3,0),"") | H25: =VENDAS_PCP!F22 -> 0 | I25: =VENDAS_PCP!G22 -> 0 | J25: =VENDAS_PCP!H22 -> 0
A26: P. BRUTO | D26: P.LIQUIDO | F26: LOTE | H26: =H25 -> 0
A28: 6 | B28: =VENDAS_PCP!B23 -> 0 | C28: =IFERROR(VLOOKUP(B13:B56,#REF!,2,0),"") | F28: =IFERROR(VLOOKUP(B28,N180:P186,3,0),"") | H28: =VENDAS_PCP!F23 -> 0 | I28: =VENDAS_PCP!G23 -> 0 | J28: =VENDAS_PCP!H23 -> 0
A29: P. BRUTO | D29: P.LIQUIDO | F29: LOTE | H29: =H28 -> 0
A31: 7 | B31: =VENDAS_PCP!B24 -> 0 | C31: =IFERROR(VLOOKUP(B13:B56,N180:O180,2,0),"") | F31: =IFERROR(VLOOKUP(B31,N180:P192,3,0),"") | H31: =VENDAS_PCP!F24 -> 0 | I31: =VENDAS_PCP!G24 -> 0 | J31: =VENDAS_PCP!H24 -> 0
A32: P. BRUTO | D32: P.LIQUIDO | F32: LOTE | H32: =H31 -> 0
A34: 8 | B34: =VENDAS_PCP!B25 -> 0 | C34: =IFERROR(VLOOKUP(B13:B56,N180:O181,2,0),"") | F34: =IFERROR(VLOOKUP(B34,N180:P192,3,0),"") | H34: =VENDAS_PCP!F25 -> 0 | I34: =VENDAS_PCP!G25 -> 0 | J34: =VENDAS_PCP!H25 -> 0
A35: P. BRUTO | D35: P.LIQUIDO | F35: LOTE | H35: =H34 -> 0
A37: 9 | B37: =VENDAS_PCP!B26 -> 0 | C37: =IFERROR(VLOOKUP(B13:B56,N180:O182,2,0),"") | F37: =IFERROR(VLOOKUP(B37,N180:P188,3,0),"") | H37: =VENDAS_PCP!F26 -> 0 | I37: =VENDAS_PCP!G26 -> 0 | J37: =VENDAS_PCP!H26 -> 0
A38: P. BRUTO | D38: P.LIQUIDO | F38: LOTE | H38: =H37 -> 0
A40: 10 | B40: =VENDAS_PCP!B27 -> 0 | C40: =IFERROR(VLOOKUP(B13:B56,N180:O183,2,0),"") | F40: =IFERROR(VLOOKUP(B40,N180:P196,3,0),"") | H40: =VENDAS_PCP!F27 -> 0 | I40: =VENDAS_PCP!G27 -> 0 | J40: =VENDAS_PCP!H27 -> 0
A41: P. BRUTO | D41: P.LIQUIDO | F41: LOTE | H41: =H40 -> 0
A43: 11 | B43: =VENDAS_PCP!B28 -> 0 | C43: =IFERROR(VLOOKUP(B13:B56,N180:O184,2,0),"") | F43: =IFERROR(VLOOKUP(B43,N180:P193,3,0),"") | H43: =VENDAS_PCP!F28 -> 0 | I43: =VENDAS_PCP!G28 -> 0 | J43: =VENDAS_PCP!H28 -> 0
A44: P. BRUTO | D44: P.LIQUIDO | F44: LOTE | H44: =H43 -> 0
A46: 12 | B46: =VENDAS_PCP!B29 -> 0 | C46: =IFERROR(VLOOKUP(B13:B56,N180:O185,2,0),"") | F46: =IFERROR(VLOOKUP(B46,N180:P197,3,0),"") | H46: =VENDAS_PCP!F29 -> 0 | I46: =VENDAS_PCP!G29 -> 0 | J46: =VENDAS_PCP!H29 -> 0
A47: P. BRUTO | D47: P.LIQUIDO | F47: LOTE | H47: =H46 -> 0
A49: 13 | B49: =VENDAS_PCP!B30 -> 0 | C49: =IFERROR(VLOOKUP(B49:B56,N180:O186,2,0),"") | F49: =IFERROR(VLOOKUP(B49,N180:P189,3,0),"") | H49: =VENDAS_PCP!F30 -> 0 | I49: =VENDAS_PCP!G30 -> 0 | J49: =VENDAS_PCP!H30 -> 0
A50: P. BRUTO | D50: P.LIQUIDO | F50: LOTE | H50: =H49 -> 0
A52: 14 | B52: =VENDAS_PCP!B31 -> 0 | C52: =IFERROR(VLOOKUP(B12:B56,N180:O187,2,0),"") | F52: =IFERROR(VLOOKUP(B52,N180:P190,3,0),"") | H52: =VENDAS_PCP!F31 -> 0 | I52: =VENDAS_PCP!G31 -> 0 | J52: =VENDAS_PCP!H31 -> 0
A53: P. BRUTO | D53: P.LIQUIDO | F53: LOTE | H53: =H52 -> 0
A55: 15 | B55: =VENDAS_PCP!B32 -> 0 | C55: =IFERROR(VLOOKUP(B13:B56,N180:O188,2,0),"") | F55: =IFERROR(VLOOKUP(B55,N180:P196,3,0),"") | H55: =VENDAS_PCP!F32 -> 0 | I55: =VENDAS_PCP!G32 -> 0 | J55: =VENDAS_PCP!H32 -> 0
A56: P. BRUTO | D56: P.LIQUIDO | F56: LOTE | H56: =H55 -> 0
A58: QTD - VOLUME: | D58: __________________________ | F58: EMBALAGEM: | H58: ___________________________
A59: P. BRUTO
...
